## 13. 예외 처리

### 13.2 예외 클래스

**이론:**

C++ 표준 라이브러리는 예외 처리를 위해 여러 가지 예외 클래스를 제공합니다. 예외 클래스는 예외 상황을 객체로 표현하며, 예외가 발생했을 때 던질 수 있습니다. 표준 라이브러리는 다양한 예외 클래스를 제공하지만, 사용자 정의 예외 클래스를 만들 수도 있습니다.

#### **표준 예외 클래스:**

표준 라이브러리의 예외 클래스들은 모두 `std::exception` 클래스를 상속받습니다. 주요 예외 클래스는 다음과 같습니다:

1. **std::exception:** 모든 표준 예외 클래스의 기본 클래스입니다. `what()` 멤버 함수를 제공하여 예외의 설명을 반환합니다.
2. **std::runtime_error:** 실행 중에 발생하는 오류를 나타냅니다.
3. **std::logic_error:** 논리적 오류를 나타냅니다.
4. **std::bad_alloc:** 메모리 할당 실패를 나타냅니다.
5. **std::out_of_range:** 범위를 벗어나는 접근을 나타냅니다.
6. **std::invalid_argument:** 잘못된 인수를 나타냅니다.

이 외에도 여러 가지 예외 클래스가 있습니다. 각각의 예외 클래스는 오류 상황에 맞는 적절한 예외를 던질 수 있도록 설계되었습니다.

#### **구문:**

표준 예외 클래스를 사용하는 기본적인 방법은 다음과 같습니다:

```cpp
#include <iostream>
#include <stdexcept> // 표준 예외 클래스를 포함합니다.
using namespace std;

void 함수() {
    throw std::runtime_error("Runtime error occurred!"); // 예외 던지기
}

int main() {
    try {
        함수();
    } catch (const std::exception& e) {
        cout << "Caught exception: " << e.what() << endl; // 예외 처리
    }
    return 0;
}
```

#### **예시:**

몇 가지 표준 예외 클래스를 사용한 예제를 통해 개념을 이해해보겠습니다.

```cpp
#include <iostream>
#include <stdexcept> // 표준 예외 클래스를 포함합니다.
using namespace std;

void checkPositive(int number) {
    if (number < 0) {
        throw std::invalid_argument("Negative number not allowed!"); // 잘못된 인수 예외 던지기
    }
}

int main() {
    try {
        checkPositive(-5);
    } catch (const std::invalid_argument& e) {
        cout << "Caught exception: " << e.what() << endl; // 예외 처리
    }

    try {
        throw std::out_of_range("Out of range error!"); // 범위 초과 예외 던지기
    } catch (const std::out_of_range& e) {
        cout << "Caught exception: " << e.what() << endl; // 예외 처리
    }

    try {
        throw std::runtime_error("Runtime error occurred!"); // 런타임 오류 예외 던지기
    } catch (const std::runtime_error& e) {
        cout << "Caught exception: " << e.what() << endl; // 예외 처리
    }

    return 0;
}
```

### 과제:

1. **예외 클래스 과제:**
   - 두 정수를 입력받아 나누는 프로그램을 작성하세요. 만약 분모가 0일 경우 `std::invalid_argument` 예외를 던지고, 배열 인덱스가 범위를 벗어날 경우 `std::out_of_range` 예외를 던지세요. 이를 처리하는 예외 처리 코드를 작성하세요.

### 해설:

1. **예외 클래스 과제 해설:**

```cpp
#include <iostream>
#include <stdexcept> // 표준 예외 클래스를 포함합니다.
using namespace std;

int divide(int numerator, int denominator) {
    if (denominator == 0) {
        throw std::invalid_argument("Division by zero!"); // 잘못된 인수 예외 던지기
    }
    return numerator / denominator;
}

void accessArray(int index, int size) {
    if (index < 0 || index >= size) {
        throw std::out_of_range("Array index out of range!"); // 범위 초과 예외 던지기
    }
    cout << "Accessing array at index " << index << endl;
}

int main() {
    int numerator, denominator;
    cout << "Enter numerator: ";
    cin >> numerator;
    cout << "Enter denominator: ";
    cin >> denominator;

    try {
        int result = divide(numerator, denominator);
        cout << "Result: " << result << endl;
    } catch (const std::invalid_argument& e) {
        cout << "Caught exception: " << e.what() << endl; // 예외 처리
    }

    int index;
    cout << "Enter array index: ";
    cin >> index;

    try {
        accessArray(index, 10); // 배열 크기는 10으로 가정
    } catch (const std::out_of_range& e) {
        cout << "Caught exception: " << e.what() << endl; // 예외 처리
    }

    return 0;
}
```

**코드 주석:**

```cpp
#include <iostream> // 표준 입출력 스트림을 포함합니다.
#include <stdexcept> // 표준 예외 클래스를 포함합니다.
using namespace std;

// 나눗셈을 수행하는 함수
int divide(int numerator, int denominator) {
    // 분모가 0이면 예외를 던짐
    if (denominator == 0) {
        throw std::invalid_argument("Division by zero!"); // 잘못된 인수 예외 던지기
    }
    return numerator / denominator;
}

// 배열에 접근하는 함수
void accessArray(int index, int size) {
    // 인덱스가 범위를 벗어나면 예외를 던짐
    if (index < 0 || index >= size) {
        throw std::out_of_range("Array index out of range!"); // 범위 초과 예외 던지기
    }
    cout << "Accessing array at index " << index << endl;
}

int main() {
    int numerator, denominator;
    cout << "Enter numerator: ";
    cin >> numerator; // 사용자로부터 분자를 입력받음
    cout << "Enter denominator: ";
    cin >> denominator; // 사용자로부터 분모를 입력받음

    try {
        // 나눗셈을 수행하고 결과를 출력함
        int result = divide(numerator, denominator);
        cout << "Result: " << result << endl;
    } catch (const std::invalid_argument& e) {
        // 분모가 0일 때 발생하는 예외를 처리함
        cout << "Caught exception: " << e.what() << endl; // 예외 처리
    }

    int index;
    cout << "Enter array index: ";
    cin >> index; // 사용자로부터 배열 인덱스를 입력받음

    try {
        // 배열에 접근하고 결과를 출력함
        accessArray(index, 10); // 배열 크기는 10으로 가정
    } catch (const std::out_of_range& e) {
        // 인덱스가 범위를 벗어날 때 발생하는 예외를 처리함
        cout << "Caught exception: " << e.what() << endl; // 예외 처리
    }

    return 0; // 프로그램이 성공적으로 종료됨을 의미합니다.
}
```
